<?xml version="1.0" ?>
<robot xmlns:xacro="https://www.ros.org/wiki/xacro">
<!-- LINK_BOGIE ********************************************************** -->
	<macro name ="link_bogie_stat" params="name orientation">
		<link name="${name}">
			<!-- values from the fusion360 files -->
		    <inertial>
		      <mass value="0.2"/>
		      <origin rpy="${1.570796*orientation} 0 0" xyz="0 ${-0.15516*orientation} 0"/>
		      <inertia ixx="0.000526666666667" ixy="0" ixz="0" iyy="0.000526666666667" iyz="0" izz="0.001"/>
		    </inertial>
		    <collision name="${name}_collision">
		      <origin rpy="${1.570796*orientation} 0 0" xyz="0 ${-0.15516*orientation} 0"/>
	      		<geometry>
				<mesh filename="package://threedrover_description/MODELS/OWR_20_BOGIE_00_ASM_STAT.stl" scale="0.001 0.001 0.001" />
  		        </geometry>
		    </collision>
		    <visual name="${name}_visual">
		      <origin rpy="${1.570796*orientation} 0 0" xyz="0 ${-0.15516*orientation} 0"/>
		      	<geometry>
				<mesh filename="package://threedrover_description/MODELS/OWR_20_BOGIE_00_ASM_STAT.stl" scale="0.001 0.001 0.001" />
		     	 </geometry>
		    </visual>
	   	</link>
    	</macro>
	<macro name ="link_bogie_rot" params="name orientation">
		<link name="${name}">
			<!-- values from the fusion360 files -->
		    <inertial>
		      <mass value="0.2"/>
		      <origin rpy="${1.570796*orientation} ${(orientation ==-1)*(3.14) +orientation*0.06925171} 0" xyz="0 ${-0.15516*orientation} 0"/>
		      <inertia ixx="0.000526666666667" ixy="0" ixz="0" iyy="0.000526666666667" iyz="0" izz="0.001"/>
		    </inertial>
		    <collision name="${name}_collision">
		      <origin rpy="${1.570796*orientation} ${(orientation ==-1)*3.14 +orientation*0.06925171} 0" xyz="0 ${-0.15516*orientation} 0"/>
	      		<geometry>
				<mesh filename="package://threedrover_description/MODELS/OWR_20_BOGIE_00_ASM_ROT.stl" scale="0.001 0.001 0.001" />
  		        </geometry>
		    </collision>
		    <visual name="${name}_visual">
		      <origin rpy="${1.570796*orientation} ${(orientation ==-1)*3.14 +orientation*0.06925171} 0" xyz="0 ${-0.15516*orientation} 0"/>
		      	<geometry>
				<mesh filename="package://threedrover_description/MODELS/OWR_20_BOGIE_00_ASM_ROT.stl" scale="0.001 0.001 0.001" />
		     	 </geometry>
		    </visual>
	   	</link>
    	</macro>

<!-- LINK_WHEEL ********************************************************** -->
	<macro name ="link_wheel_stat" params="name orientation end">
		<link name="${name}">
			<!-- values from the fusion360 files -->
		    <inertial>
		      <mass value="0.2"/>
		      <origin rpy="${1.570796*orientation} 0 0" xyz="${-0.3865*end} ${-(0.15516+0.134 + 0.078)*orientation} -0.22012"/>
		      <inertia ixx="0.000526666666667" ixy="0" ixz="0" iyy="0.000526666666667" iyz="0" izz="0.001"/>
		    </inertial>
		    <collision name="${name}_collision">
		      <origin rpy="${1.570796*orientation} 0 0" xyz="${-0.3865*end} ${-(0.15516+0.134 + 0.078)*orientation} -0.22012"/>
	      		<geometry>
				<mesh filename="package://threedrover_description/MODELS/OWR_20_DRIVE_00_ASM_STAT.stl" scale="0.001 0.001 0.001" />
  		        </geometry>
		    </collision>
		    <visual name="${name}_visual">
		      <origin rpy="${1.570796*orientation} 0 0" xyz="${-0.3865*end} ${-(0.15516+0.134 + 0.078)*orientation} -0.22012"/>
		      	<geometry>
				<mesh filename="package://threedrover_description/MODELS/OWR_20_DRIVE_00_ASM_STAT.stl" scale="0.001 0.001 0.001" />
		     	 </geometry>
		    </visual>
	   	</link>
    	</macro>
	<macro name ="link_wheel_rot" params="name orientation end">
		<link name="${name}">
			<!-- values from the fusion360 files -->
		    <inertial>
		      <mass value="0.2"/>
		      <origin rpy="${1.570796*orientation} ${(orientation ==-1)*3.14} 0" xyz="${-0.3865*end} ${-(0.15516+0.134 + 0.078)*orientation} -0.22012"/>
		      <inertia ixx="0.000526666666667" ixy="0" ixz="0" iyy="0.000526666666667" iyz="0" izz="0.001"/>
		    </inertial>
		    <collision name="${name}_collision">
		      <origin rpy="${1.570796*orientation} ${(orientation ==-1)*3.14} 0" xyz="${-0.3865*end} ${-(0.15516+0.134 + 0.078)*orientation} -0.22012"/>
	      		<geometry>
				<mesh filename="package://threedrover_description/MODELS/OWR_20_DRIVE_00_ASM_ROT.stl" scale="0.001 0.001 0.001" />
  		        </geometry>
		    </collision>
		    <visual name="${name}_visual">
		      <origin rpy="${1.570796*orientation} ${(orientation ==-1)*3.14} 0" xyz="${-0.3865*end} ${-(0.15516+0.134 + 0.078)*orientation} -0.22012"/>
		      	<geometry>
				<mesh filename="package://threedrover_description/MODELS/OWR_20_DRIVE_00_ASM_ROT.stl" scale="0.001 0.001 0.001" />
		     	 </geometry>
		    </visual>
	   	</link>
    	</macro>


<!-- JOINTS ********************************************************** -->
	<macro name="joint_stat" params="name child parent origin_xyz" >
    		<joint name="${name}" type="fixed">
			<origin rpy="0 0 0" xyz="${origin_xyz}"/>
			<child link="${child}"/>
			<parent link="link_chassis"/>
			<axis rpy="1.570796 0 0" xyz="0 1 0"/>
			<limit effort="10000" velocity="1000"/>
			<joint_properties damping="1.0" friction="1.0"/>
		</joint>
    	</macro>
	<macro name="joint_rot" params="name child parent origin_xyz" >
    		<joint name="${name}" type="continuous">
			<origin rpy="0 0 0" xyz="${origin_xyz}"/>
			<child link="${child}"/>
			<parent link="${parent}"/>
			<axis rpy="0 0 0" xyz="0 1 0"/>
			<limit effort="10000" velocity="1000"/>
			<joint_properties damping="1.0" friction="1.0"/>
		</joint>
    	</macro>
</robot>
