<?xml version="1.0" encoding="utf-8"?>
<!-- =================================================================================== -->
<!-- |    This document was autogenerated by xacro from rover.xacro                    | -->
<!-- |    EDITING THIS FILE BY HAND IS NOT RECOMMENDED                                 | -->
<!-- =================================================================================== -->
<robot name="plasticRover">
  <material name="black">
    <color rgba="0.0 0.0 0.0 1.0"/>
  </material>
  <material name="blue">
    <color rgba="0.203125 0.23828125 0.28515625 1.0"/>
  </material>
  <material name="green">
    <color rgba="0.0 0.8 0.0 1.0"/>
  </material>
  <material name="grey">
    <color rgba="0.2 0.2 0.2 1.0"/>
  </material>
  <material name="orange">
    <color rgba="1.0 0.423529411765 0.0392156862745 1.0"/>
  </material>
  <material name="brown">
    <color rgba="0.870588235294 0.811764705882 0.764705882353 1.0"/>
  </material>
  <material name="red">
    <color rgba="0.80078125 0.12890625 0.1328125 1.0"/>
  </material>
  <material name="white">
    <color rgba="1.0 1.0 1.0 1.0"/>
  </material>
  <gazebo>
    <plugin filename="libgazebo_ros_skid_steer_drive.so" name="ss_drive">
      <updateRate>100.0</updateRate>
      <robotNamespace>/</robotNamespace>
      <leftFrontJoint>wheel_FL</leftFrontJoint>
      <rightFrontJoint>wheel_FR</rightFrontJoint>
      <leftRearJoint>wheel_BL</leftRearJoint>
      <rightRearJoint>wheel_BR</rightRearJoint>
      <wheelSeparation>0.77</wheelSeparation>
      <wheelDiameter>0.2</wheelDiameter>
      <robotBaseFrame>link_chassis</robotBaseFrame>
      <torque>10</torque>
      <topicName>cmd_vel</topicName>
      <broadcastTF>false</broadcastTF>
    </plugin>
  </gazebo>
  <gazebo reference="camera_link">
    <sensor name="camera1" type="camera">
      <update_rate>30.0</update_rate>
      <camera name="head">
        <horizontal_fov>1.3962634</horizontal_fov>
        <image>
          <width>800</width>
          <height>800</height>
          <format>R8G8B8</format>
        </image>
        <clip>
          <near>0.02</near>
          <far>300</far>
        </clip>
        <noise>
          <type>gaussian</type>
          <!-- Noise is sampled independently per pixel on each frame.
		       That pixel's noise value is added to each of its color
		       channels, which at that point lie in the range [0,1]. -->
          <mean>0.0</mean>
          <stddev>0.007</stddev>
        </noise>
      </camera>
      <plugin filename="libgazebo_ros_camera.so" name="camera_controller">
        <alwaysOn>true</alwaysOn>
        <updateRate>0.0</updateRate>
        <cameraName>rover/camera1</cameraName>
        <imageTopicName>image_raw</imageTopicName>
        <cameraInfoTopicName>camera_info</cameraInfoTopicName>
        <frameName>camera_link</frameName>
        <hackBaseline>0.07</hackBaseline>
        <distortionK1>0.0</distortionK1>
        <distortionK2>0.0</distortionK2>
        <distortionK3>0.0</distortionK3>
        <distortionT1>0.0</distortionT1>
        <distortionT2>0.0</distortionT2>
      </plugin>
    </sensor>
  </gazebo>
  <gazebo reference="lidar_link">
    <sensor name="head_hokuyo_sensor" type="ray">
      <pose>0 0 0 0 0 0</pose>
      <visualize>false</visualize>
      <update_rate>40</update_rate>
      <ray>
        <scan>
          <horizontal>
            <samples>720</samples>
            <resolution>1</resolution>
            <min_angle>-1.570796</min_angle>
            <max_angle>1.570796</max_angle>
          </horizontal>
        </scan>
        <range>
          <min>0.10</min>
          <max>30.0</max>
          <resolution>0.01</resolution>
        </range>
        <noise>
          <type>gaussian</type>
          <!-- Noise parameters based on published spec for Hokuyo laser
               achieving "+-30mm" accuracy at range < 10m.  A mean of 0.0m and
               stddev of 0.01m will put 99.7% of samples within 0.03m of the true
               reading. -->
          <mean>0.0</mean>
          <stddev>0.01</stddev>
        </noise>
      </ray>
      <plugin filename="libgazebo_ros_laser.so" name="gazebo_ros_head_hokuyo_controller">
        <topicName>/rover/laser/scan</topicName>
        <frameName>lidar_link</frameName>
      </plugin>
    </sensor>
  </gazebo>
  <link name="link_chassis">
    <!-- values calculated in fusion360 -->
    <inertial>
      <mass value="2.441483"/>
      <origin rpy="0 0 0" xyz="0  0 0"/>
      <inertia ixx="0.061" ixy="0.0003601" ixz="-2.478e-05" iyy="0.119" iyz="5.191e-07" izz="0.081"/>
    </inertial>
    <collision>
      <geometry>
        <!--Again this is from the fusion360-->
        <box size="0.511 0.4 0.208"/>
      </geometry>
      <origin rpy="1.570796 0 0" xyz="0 0 0"/>
    </collision>
    <visual>
      <geometry>
        <!--<mesh filename="package://threedrover_description/MODELS/OWR_20_CHASSIS_00_ASM.stl" scale="0.001 0.001 0.001" />-->
        <box size="0.511 0.208 0.4"/>
      </geometry>
      <origin rpy="1.570796 0 0" xyz="0 0 0"/>
      <material name="white"/>
    </visual>
  </link>
  <!-- Differential -->
  <!-- Diif bar -->
  <link name="link_right_bogie_stat">
    <!-- values from the fusion360 files -->
    <inertial>
      <mass value="0.441"/>
      <origin rpy="0 0 0" xyz="-0.00000069097  0.0002123 0.038"/>
      <inertia ixx="0.002" ixy="-0.00003576" ixz="-0.000000003393" iyy="0.000779" iyz="0.00000003725" izz="0.002"/>
    </inertial>
    <!--  <inertial>
		      <mass value="0.441"/>
		      <inertia ixx="0.000526666666667" ixy="0" ixz="0" iyy="0.000526666666667" iyz="0" izz="0.001"/>
		    </inertial> -->
    <collision name="link_right_bogie_stat_collision">
      <geometry>
        <cylinder length="0.05" radius="0.05"/>
        <!--<mesh filename="package://threedrover_description/MODELS/OWR_20_BOGIE_00_ASM_STAT.stl" scale="0.001 0.001 0.001" />-->
      </geometry>
    </collision>
    <visual name="link_right_bogie_stat_visual">
      <geometry>
        <cylinder length="0.05" radius="0.05"/>
        <!--<mesh filename="package://threedrover_description/MODELS/OWR_20_BOGIE_00_ASM_STAT.stl" scale="0.001 0.001 0.001" />-->
      </geometry>
    </visual>
  </link>
  <link name="link_right_bogie_rot">
    <!-- values from the fusion360 files -->
    <inertial>
      <mass value="0.871251"/>
      <origin rpy="0 0 0" xyz="0.004  -0.077 0.091"/>
      <inertia ixx="0.009" ixy="-0.002" ixz="-9.081e-05" iyy="0.039" iyz="0.002" izz="0.045"/>
    </inertial>
    <visual name="link_right_bogie_rot_visual">
      <geometry>
        <mesh filename="package://threedrover_description/MODELS/OWR_20_BOGIE_00_ASM_ROT.stl" scale="0.001 0.001 0.001"/>
      </geometry>
    </visual>
  </link>
  <link name="link_left_bogie_stat">
    <!-- values from the fusion360 files -->
    <inertial>
      <mass value="0.441"/>
      <origin rpy="0 0 0" xyz="-0.00000069097  0.0002123 0.038"/>
      <inertia ixx="0.002" ixy="-0.00003576" ixz="-0.000000003393" iyy="0.000779" iyz="0.00000003725" izz="0.002"/>
    </inertial>
    <!--  <inertial>
		      <mass value="0.441"/>
		      <inertia ixx="0.000526666666667" ixy="0" ixz="0" iyy="0.000526666666667" iyz="0" izz="0.001"/>
		    </inertial> -->
    <collision name="link_left_bogie_stat_collision">
      <geometry>
        <cylinder length="0.05" radius="0.05"/>
        <!--<mesh filename="package://threedrover_description/MODELS/OWR_20_BOGIE_00_ASM_STAT.stl" scale="0.001 0.001 0.001" />-->
      </geometry>
    </collision>
    <visual name="link_left_bogie_stat_visual">
      <geometry>
        <cylinder length="0.05" radius="0.05"/>
        <!--<mesh filename="package://threedrover_description/MODELS/OWR_20_BOGIE_00_ASM_STAT.stl" scale="0.001 0.001 0.001" />-->
      </geometry>
    </visual>
  </link>
  <link name="link_left_bogie_rot">
    <!-- values from the fusion360 files -->
    <inertial>
      <mass value="0.871251"/>
      <origin rpy="0 0 0" xyz="0.004  -0.077 0.091"/>
      <inertia ixx="0.009" ixy="-0.002" ixz="-9.081e-05" iyy="0.039" iyz="0.002" izz="0.045"/>
    </inertial>
    <visual name="link_left_bogie_rot_visual">
      <geometry>
        <mesh filename="package://threedrover_description/MODELS/OWR_20_BOGIE_00_ASM_ROT.stl" scale="0.001 0.001 0.001"/>
      </geometry>
    </visual>
  </link>
  <joint name="joint_bogie_left_stat" type="fixed">
    <!-- <origin rpy="${1.570796*orientation} 0 0" xyz="0 ${-0.15516*orientation} 0"/> -->
    <origin rpy="-1.570796 0 0" xyz="0 0.15516 0"/>
    <child link="link_left_bogie_stat"/>
    <parent link="link_chassis"/>
    <axis rpy="1.570796 0 0" xyz="0 1 0"/>
    <limit effort="10000" velocity="1000"/>
    <joint_properties damping="1.0" friction="1.0"/>
  </joint>
  <joint name="joint_bogie_right_stat" type="fixed">
    <!-- <origin rpy="${1.570796*orientation} 0 0" xyz="0 ${-0.15516*orientation} 0"/> -->
    <origin rpy="1.570796 0 0" xyz="0 -0.15516 0"/>
    <child link="link_right_bogie_stat"/>
    <parent link="link_chassis"/>
    <axis rpy="1.570796 0 0" xyz="0 1 0"/>
    <limit effort="10000" velocity="1000"/>
    <joint_properties damping="1.0" friction="1.0"/>
  </joint>
  <joint name="joint_bogie_right_rot" type="continuous">
    <!-- <origin rpy="0 ${(orientation ==-1)*3.14 + orientation*0.06925171} 0" xyz="0 0 0"/> -->
    <origin rpy="0 0 0.0" xyz="0 0 0"/>
    <child link="link_right_bogie_rot"/>
    <parent link="link_right_bogie_stat"/>
    <axis rpy="0 0 0" xyz="0 0 1"/>
    <limit effort="10000" velocity="1000"/>
    <joint_properties damping="1.0" friction="1.0"/>
  </joint>
  <joint name="joint_bogie_left_rot" type="continuous">
    <!-- <origin rpy="0 ${(orientation ==-1)*3.14 + orientation*0.06925171} 0" xyz="0 0 0"/> -->
    <origin rpy="0 0 3.14159" xyz="0 0 0"/>
    <child link="link_left_bogie_rot"/>
    <parent link="link_left_bogie_stat"/>
    <axis rpy="0 0 0" xyz="0 0 1"/>
    <limit effort="10000" velocity="1000"/>
    <joint_properties damping="1.0" friction="1.0"/>
  </joint>
  <!-- Wheel -->
  <link name="link_FRSWheel">
    <!-- values from the fusion360 files -->
    <inertial>
      <mass value="1.397"/>
      <origin rpy="0 0 0" xyz="0.003  -0.003 0.013"/>
      <inertia ixx="0.002" ixy="-0.000006590" ixz="0.0001390" iyy="0.002" iyz="-0.0000004779" izz="0.002"/>
    </inertial>
    <collision name="link_FRSWheel_collision">
      <geometry>
        <cylinder length="0.05" radius="0.05"/>
      </geometry>
    </collision>
    <visual name="link_FRSWheel_visual">
      <geometry>
        <cylinder length="0.05" radius="0.05"/>
        <!-- <mesh filename="package://threedrover_description/MODELS/OWR_20_DRIVE_00_ASM_STAT.stl" scale="0.001 0.001 0.001" /> -->
      </geometry>
    </visual>
  </link>
  <link name="link_FLSWheel">
    <!-- values from the fusion360 files -->
    <inertial>
      <mass value="1.397"/>
      <origin rpy="0 0 0" xyz="0.003  -0.003 0.013"/>
      <inertia ixx="0.002" ixy="-0.000006590" ixz="0.0001390" iyy="0.002" iyz="-0.0000004779" izz="0.002"/>
    </inertial>
    <collision name="link_FLSWheel_collision">
      <geometry>
        <cylinder length="0.05" radius="0.05"/>
      </geometry>
    </collision>
    <visual name="link_FLSWheel_visual">
      <geometry>
        <cylinder length="0.05" radius="0.05"/>
        <!-- <mesh filename="package://threedrover_description/MODELS/OWR_20_DRIVE_00_ASM_STAT.stl" scale="0.001 0.001 0.001" /> -->
      </geometry>
    </visual>
  </link>
  <link name="link_BRSWheel">
    <!-- values from the fusion360 files -->
    <inertial>
      <mass value="1.397"/>
      <origin rpy="0 0 0" xyz="0.003  -0.003 0.013"/>
      <inertia ixx="0.002" ixy="-0.000006590" ixz="0.0001390" iyy="0.002" iyz="-0.0000004779" izz="0.002"/>
    </inertial>
    <collision name="link_BRSWheel_collision">
      <geometry>
        <cylinder length="0.05" radius="0.05"/>
      </geometry>
    </collision>
    <visual name="link_BRSWheel_visual">
      <geometry>
        <cylinder length="0.05" radius="0.05"/>
        <!-- <mesh filename="package://threedrover_description/MODELS/OWR_20_DRIVE_00_ASM_STAT.stl" scale="0.001 0.001 0.001" /> -->
      </geometry>
    </visual>
  </link>
  <link name="link_BLSWheel">
    <!-- values from the fusion360 files -->
    <inertial>
      <mass value="1.397"/>
      <origin rpy="0 0 0" xyz="0.003  -0.003 0.013"/>
      <inertia ixx="0.002" ixy="-0.000006590" ixz="0.0001390" iyy="0.002" iyz="-0.0000004779" izz="0.002"/>
    </inertial>
    <collision name="link_BLSWheel_collision">
      <geometry>
        <cylinder length="0.05" radius="0.05"/>
      </geometry>
    </collision>
    <visual name="link_BLSWheel_visual">
      <geometry>
        <cylinder length="0.05" radius="0.05"/>
        <!-- <mesh filename="package://threedrover_description/MODELS/OWR_20_DRIVE_00_ASM_STAT.stl" scale="0.001 0.001 0.001" /> -->
      </geometry>
    </visual>
  </link>
  <joint name="wheelmount_FL" type="fixed">
    <!-- one leg goes (0.4006 and -0.193183) while the other goes (-0.370 and -0.247057)  using vector magic the
				wheel positions can be paramaterised for end =1 or end = -1 -->
    <origin rpy="0 0 -1.570796" xyz="-0.37 -0.247057 0.17"/>
    <child link="link_FLSWheel"/>
    <parent link="link_left_bogie_rot"/>
    <axis rpy="1.570796 0 0" xyz="0 0 1"/>
    <limit effort="10000" velocity="1000"/>
    <joint_properties damping="1.0" friction="1.0"/>
  </joint>
  <joint name="wheelmount_BL" type="fixed">
    <!-- one leg goes (0.4006 and -0.193183) while the other goes (-0.370 and -0.247057)  using vector magic the
				wheel positions can be paramaterised for end =1 or end = -1 -->
    <origin rpy="0 0 -1.570796" xyz="0.4006 -0.193183 0.17"/>
    <child link="link_BLSWheel"/>
    <parent link="link_left_bogie_rot"/>
    <axis rpy="1.570796 0 0" xyz="0 0 1"/>
    <limit effort="10000" velocity="1000"/>
    <joint_properties damping="1.0" friction="1.0"/>
  </joint>
  <joint name="wheelmount_FR" type="fixed">
    <!-- one leg goes (0.4006 and -0.193183) while the other goes (-0.370 and -0.247057)  using vector magic the
				wheel positions can be paramaterised for end =1 or end = -1 -->
    <origin rpy="0 0 1.570796" xyz="0.4006 -0.193183 0.17"/>
    <child link="link_FRSWheel"/>
    <parent link="link_right_bogie_rot"/>
    <axis rpy="1.570796 0 0" xyz="0 0 1"/>
    <limit effort="10000" velocity="1000"/>
    <joint_properties damping="1.0" friction="1.0"/>
  </joint>
  <joint name="wheelmount_BR" type="fixed">
    <!-- one leg goes (0.4006 and -0.193183) while the other goes (-0.370 and -0.247057)  using vector magic the
				wheel positions can be paramaterised for end =1 or end = -1 -->
    <origin rpy="0 0 1.570796" xyz="-0.37 -0.247057 0.17"/>
    <child link="link_BRSWheel"/>
    <parent link="link_right_bogie_rot"/>
    <axis rpy="1.570796 0 0" xyz="0 0 1"/>
    <limit effort="10000" velocity="1000"/>
    <joint_properties damping="1.0" friction="1.0"/>
  </joint>
  <link name="link_FRRWheel">
    <!-- values from the fusion360 files -->
    <inertial>
      <mass value="6.598"/>
      <origin rpy="0 0 0" xyz="-0.003  -0.003 0.026"/>
      <inertia ixx="0.031" ixy="0.0000002489" ixz="-0.000000001240" iyy="0.031" iyz="0.00000001531" izz="0.051"/>
    </inertial>
    <collision name="link_FRRWheel_collision">
      <geometry>
        <!--	<mesh filename="package://threedrover_description/MODELS/OWR_20_DRIVE_00_ASM_ROT.stl" scale="0.001 0.001 0.001" /> -->
        <cylinder length="0.098" radius="0.1"/>
      </geometry>
    </collision>
    <visual name="link_FRRWheel_visual">
      <geometry>
        <mesh filename="package://threedrover_description/MODELS/OWR_20_DRIVE_00_ASM_ROT.stl" scale="0.001 0.001 0.001"/>
        <!--<cylinder length="0.098" radius="0.1"/> -->
      </geometry>
    </visual>
  </link>
  <link name="link_BRRWheel">
    <!-- values from the fusion360 files -->
    <inertial>
      <mass value="6.598"/>
      <origin rpy="0 0 0" xyz="-0.003  -0.003 0.026"/>
      <inertia ixx="0.031" ixy="0.0000002489" ixz="-0.000000001240" iyy="0.031" iyz="0.00000001531" izz="0.051"/>
    </inertial>
    <collision name="link_BRRWheel_collision">
      <geometry>
        <!--	<mesh filename="package://threedrover_description/MODELS/OWR_20_DRIVE_00_ASM_ROT.stl" scale="0.001 0.001 0.001" /> -->
        <cylinder length="0.098" radius="0.1"/>
      </geometry>
    </collision>
    <visual name="link_BRRWheel_visual">
      <geometry>
        <mesh filename="package://threedrover_description/MODELS/OWR_20_DRIVE_00_ASM_ROT.stl" scale="0.001 0.001 0.001"/>
        <!--<cylinder length="0.098" radius="0.1"/> -->
      </geometry>
    </visual>
  </link>
  <link name="link_FLRWheel">
    <!-- values from the fusion360 files -->
    <inertial>
      <mass value="6.598"/>
      <origin rpy="0 0 0" xyz="-0.003  -0.003 0.026"/>
      <inertia ixx="0.031" ixy="0.0000002489" ixz="-0.000000001240" iyy="0.031" iyz="0.00000001531" izz="0.051"/>
    </inertial>
    <collision name="link_FLRWheel_collision">
      <geometry>
        <!--	<mesh filename="package://threedrover_description/MODELS/OWR_20_DRIVE_00_ASM_ROT.stl" scale="0.001 0.001 0.001" /> -->
        <cylinder length="0.098" radius="0.1"/>
      </geometry>
    </collision>
    <visual name="link_FLRWheel_visual">
      <geometry>
        <mesh filename="package://threedrover_description/MODELS/OWR_20_DRIVE_00_ASM_ROT.stl" scale="0.001 0.001 0.001"/>
        <!--<cylinder length="0.098" radius="0.1"/> -->
      </geometry>
    </visual>
  </link>
  <link name="link_BLRWheel">
    <!-- values from the fusion360 files -->
    <inertial>
      <mass value="6.598"/>
      <origin rpy="0 0 0" xyz="-0.003  -0.003 0.026"/>
      <inertia ixx="0.031" ixy="0.0000002489" ixz="-0.000000001240" iyy="0.031" iyz="0.00000001531" izz="0.051"/>
    </inertial>
    <collision name="link_BLRWheel_collision">
      <geometry>
        <!--	<mesh filename="package://threedrover_description/MODELS/OWR_20_DRIVE_00_ASM_ROT.stl" scale="0.001 0.001 0.001" /> -->
        <cylinder length="0.098" radius="0.1"/>
      </geometry>
    </collision>
    <visual name="link_BLRWheel_visual">
      <geometry>
        <mesh filename="package://threedrover_description/MODELS/OWR_20_DRIVE_00_ASM_ROT.stl" scale="0.001 0.001 0.001"/>
        <!--<cylinder length="0.098" radius="0.1"/> -->
      </geometry>
    </visual>
  </link>
  <joint name="wheel_FL" type="continuous">
    <!--<origin rpy="0 0 0" xyz="${-0.3865*end} ${-(0.15516+0.134 + 0.078)*orientation} -0.22012"/> -->
    <!--
			<origin rpy="${1.570796*orientation} ${(orientation ==-1)*3.14} 0" xyz="${-0.3865*end} ${-(0.15516+0.134 + 0.078)*orientation} -0.22012"/> -->
    <origin rpy="0 0 -1.570796" xyz="0 0 0.05"/>
    <child link="link_FLRWheel"/>
    <parent link="link_FLSWheel"/>
    <axis rpy="0 0 0" xyz="0 0 1"/>
    <limit effort="10000" velocity="1000"/>
    <joint_properties damping="1.0" friction="1.0"/>
  </joint>
  <joint name="wheel_BL" type="continuous">
    <!--<origin rpy="0 0 0" xyz="${-0.3865*end} ${-(0.15516+0.134 + 0.078)*orientation} -0.22012"/> -->
    <!--
			<origin rpy="${1.570796*orientation} ${(orientation ==-1)*3.14} 0" xyz="${-0.3865*end} ${-(0.15516+0.134 + 0.078)*orientation} -0.22012"/> -->
    <origin rpy="0 0 -1.570796" xyz="0 0 0.05"/>
    <child link="link_BLRWheel"/>
    <parent link="link_BLSWheel"/>
    <axis rpy="0 0 0" xyz="0 0 1"/>
    <limit effort="10000" velocity="1000"/>
    <joint_properties damping="1.0" friction="1.0"/>
  </joint>
  <joint name="wheel_FR" type="continuous">
    <!--<origin rpy="0 0 0" xyz="${-0.3865*end} ${-(0.15516+0.134 + 0.078)*orientation} -0.22012"/> -->
    <!--
			<origin rpy="${1.570796*orientation} ${(orientation ==-1)*3.14} 0" xyz="${-0.3865*end} ${-(0.15516+0.134 + 0.078)*orientation} -0.22012"/> -->
    <origin rpy="0 0 1.570796" xyz="0 0 0.05"/>
    <child link="link_FRRWheel"/>
    <parent link="link_FRSWheel"/>
    <axis rpy="0 0 0" xyz="0 0 1"/>
    <limit effort="10000" velocity="1000"/>
    <joint_properties damping="1.0" friction="1.0"/>
  </joint>
  <joint name="wheel_BR" type="continuous">
    <!--<origin rpy="0 0 0" xyz="${-0.3865*end} ${-(0.15516+0.134 + 0.078)*orientation} -0.22012"/> -->
    <!--
			<origin rpy="${1.570796*orientation} ${(orientation ==-1)*3.14} 0" xyz="${-0.3865*end} ${-(0.15516+0.134 + 0.078)*orientation} -0.22012"/> -->
    <origin rpy="0 0 1.570796" xyz="0 0 0.05"/>
    <child link="link_BRRWheel"/>
    <parent link="link_BRSWheel"/>
    <axis rpy="0 0 0" xyz="0 0 1"/>
    <limit effort="10000" velocity="1000"/>
    <joint_properties damping="1.0" friction="1.0"/>
  </joint>
  <link name="camera_link">
    <visual>
      <geometry>
        <box size="0.1 0.1 0.1"/>
      </geometry>
    </visual>
    <origin rpy="0 0 0" xyz="0 0 0"/>
    <material name="green"/>
  </link>
  <link name="lidar_link">
    <visual>
      <geometry>
        <box size="0.05 0.05 0.1"/>
      </geometry>
    </visual>
    <origin rpy="0 0 0" xyz="0 0 0"/>
    <material name="green"/>
  </link>
  <joint name="camera_joint" type="fixed">
    <!-- <origin rpy="${1.570796*orientation} 0 0" xyz="0 ${-0.15516*orientation} 0"/> -->
    <origin rpy="0 0 0" xyz="0.2555 0 0"/>
    <child link="camera_link"/>
    <parent link="link_chassis"/>
    <axis rpy="1.570796 0 0" xyz="0 1 0"/>
    <limit effort="10000" velocity="1000"/>
    <joint_properties damping="1.0" friction="1.0"/>
  </joint>
  <joint name="lidar_joint" type="fixed">
    <!-- <origin rpy="${1.570796*orientation} 0 0" xyz="0 ${-0.15516*orientation} 0"/> -->
    <origin rpy="0 0 0" xyz="0.2275 0 0.104"/>
    <child link="lidar_link"/>
    <parent link="link_chassis"/>
    <axis rpy="1.570796 0 0" xyz="0 1 0"/>
    <limit effort="10000" velocity="1000"/>
    <joint_properties damping="1.0" friction="1.0"/>
  </joint>
</robot>

