<sdf version='1.6'>
  <model name='plasticRover'>
    <link name='link_chassis'>
      <pose frame=''>0 0 0 0 -0 0</pose>
      <inertial>
        <pose frame=''>-0 0 0 0 -0 0</pose>
        <mass>3.32348</mass>
        <inertia>
          <ixx>0.0979082</ixx>
          <ixy>0.0003601</ixy>
          <ixz>-2.478e-05</ixz>
          <iyy>0.123</iyy>
          <iyz>3.66135e-05</iyz>
          <izz>0.115466</izz>
        </inertia>
      </inertial>
      <collision name='link_chassis_collision'>
        <pose frame=''>0 0 0 1.5708 -0 0</pose>
        <geometry>
          <box>
            <size>0.511 0.4 0.208</size>
          </box>
        </geometry>
      </collision>
      <collision name='link_chassis_fixed_joint_lump__link_left_bogie_stat_collision_collision_1'>
        <pose frame=''>0 0.15516 0 -1.5708 0 0</pose>
        <geometry>
          <cylinder>
            <length>0.05</length>
            <radius>0.05</radius>
          </cylinder>
        </geometry>
      </collision>
      <collision name='link_chassis_fixed_joint_lump__link_right_bogie_stat_collision_collision_2'>
        <pose frame=''>0 -0.15516 0 1.5708 -0 0</pose>
        <geometry>
          <cylinder>
            <length>0.05</length>
            <radius>0.05</radius>
          </cylinder>
        </geometry>
      </collision>
      <visual name='link_chassis_visual'>
        <pose frame=''>0 0 0 1.5708 -0 0</pose>
        <geometry>
          <box>
            <size>0.511 0.208 0.4</size>
          </box>
        </geometry>
      </visual>
      <visual name='link_chassis_fixed_joint_lump__camera_link_visual_1'>
        <pose frame=''>0.2555 0 0 0 -0 0</pose>
        <geometry>
          <box>
            <size>0.1 0.1 0.1</size>
          </box>
        </geometry>
        <material>
          <script>
            <uri>__default__</uri>
            <name>__default__</name>
          </script>
        </material>
      </visual>
      <visual name='link_chassis_fixed_joint_lump__link_left_bogie_stat_visual_visual_2'>
        <pose frame=''>0 0.15516 0 -1.5708 0 0</pose>
        <geometry>
          <cylinder>
            <length>0.05</length>
            <radius>0.05</radius>
          </cylinder>
        </geometry>
      </visual>
      <visual name='link_chassis_fixed_joint_lump__link_right_bogie_stat_visual_visual_3'>
        <pose frame=''>0 -0.15516 0 1.5708 -0 0</pose>
        <geometry>
          <cylinder>
            <length>0.05</length>
            <radius>0.05</radius>
          </cylinder>
        </geometry>
      </visual>
      <visual name='link_chassis_fixed_joint_lump__lidar_link_visual_4'>
        <pose frame=''>0.2275 0 0.104 0 -0 0</pose>
        <geometry>
          <box>
            <size>0.05 0.05 0.1</size>
          </box>
        </geometry>
        <material>
          <script>
            <uri>__default__</uri>
            <name>__default__</name>
          </script>
        </material>
      </visual>
      <velocity_decay/>
      <sensor name='camera1' type='camera'>
        <update_rate>30</update_rate>
        <camera name='head'>
          <horizontal_fov>1.39626</horizontal_fov>
          <image>
            <width>800</width>
            <height>800</height>
            <format>R8G8B8</format>
          </image>
          <clip>
            <near>0.02</near>
            <far>300</far>
          </clip>
          <noise>
            <type>gaussian</type>
            <mean>0</mean>
            <stddev>0.007</stddev>
          </noise>
        </camera>
        <plugin name='camera_controller' filename='libgazebo_ros_camera.so'>
          <alwaysOn>1</alwaysOn>
          <updateRate>0.0</updateRate>
          <cameraName>rover/camera1</cameraName>
          <imageTopicName>image_raw</imageTopicName>
          <cameraInfoTopicName>camera_info</cameraInfoTopicName>
          <frameName>camera_link</frameName>
          <hackBaseline>0.07</hackBaseline>
          <distortionK1>0.0</distortionK1>
          <distortionK2>0.0</distortionK2>
          <distortionK3>0.0</distortionK3>
          <distortionT1>0.0</distortionT1>
          <distortionT2>0.0</distortionT2>
        </plugin>
        <pose frame=''>0.2555 0 0 0 -0 0</pose>
      </sensor>
      <gravity>1</gravity>
      <velocity_decay/>
      <sensor name='head_hokuyo_sensor' type='ray'>
        <visualize>0</visualize>
        <update_rate>40</update_rate>
        <ray>
          <scan>
            <horizontal>
              <samples>720</samples>
              <resolution>1</resolution>
              <min_angle>-1.5708</min_angle>
              <max_angle>1.5708</max_angle>
            </horizontal>
          </scan>
          <range>
            <min>0.1</min>
            <max>30</max>
            <resolution>0.01</resolution>
          </range>
          <noise>
            <type>gaussian</type>
            <mean>0</mean>
            <stddev>0.01</stddev>
          </noise>
        </ray>
        <plugin name='gazebo_ros_head_hokuyo_controller' filename='libgazebo_ros_laser.so'>
          <topicName>/rover/laser/scan</topicName>
          <frameName>lidar_link</frameName>
        </plugin>
        <pose frame=''>0.2275 0 0.104 0 -0 0</pose>
      </sensor>
    </link>
    <link name='link_left_bogie_rot'>
      <pose frame=''>0 0.15516 0 1.5708 3e-06 3.14159</pose>
      <inertial>
        <pose frame=''>0.010327 -0.188386 0.161131 0 -0 0</pose>
        <mass>3.66525</mass>
        <inertia>
          <ixx>0.034829</ixx>
          <ixy>-0.0301798</ixy>
          <ixz>-0.00059891</ixz>
          <iyy>0.463453</iyy>
          <iyz>0.0106502</iyz>
          <izz>0.48004</izz>
        </inertia>
      </inertial>
      <collision name='link_left_bogie_rot_fixed_joint_lump__link_BLSWheel_collision_collision'>
        <pose frame=''>0.4006 -0.193183 0.17 0 0 -1.5708</pose>
        <geometry>
          <cylinder>
            <length>0.05</length>
            <radius>0.05</radius>
          </cylinder>
        </geometry>
      </collision>
      <collision name='link_left_bogie_rot_fixed_joint_lump__link_FLSWheel_collision_collision_1'>
        <pose frame=''>-0.37 -0.247057 0.17 0 0 -1.5708</pose>
        <geometry>
          <cylinder>
            <length>0.05</length>
            <radius>0.05</radius>
          </cylinder>
        </geometry>
      </collision>
      <visual name='link_left_bogie_rot_visual_visual'>
        <pose frame=''>0 0 0 0 -0 0</pose>
        <geometry>
          <mesh>
            <scale>0.001 0.001 0.001</scale>
            <uri>model://threedrover_description/MODELS/OWR_20_BOGIE_00_ASM_ROT.stl</uri>
          </mesh>
        </geometry>
      </visual>
      <visual name='link_left_bogie_rot_fixed_joint_lump__link_BLSWheel_visual_visual_1'>
        <pose frame=''>0.4006 -0.193183 0.17 0 0 -1.5708</pose>
        <geometry>
          <cylinder>
            <length>0.05</length>
            <radius>0.05</radius>
          </cylinder>
        </geometry>
      </visual>
      <visual name='link_left_bogie_rot_fixed_joint_lump__link_FLSWheel_visual_visual_2'>
        <pose frame=''>-0.37 -0.247057 0.17 0 0 -1.5708</pose>
        <geometry>
          <cylinder>
            <length>0.05</length>
            <radius>0.05</radius>
          </cylinder>
        </geometry>
      </visual>
    </link>
    <joint name='joint_bogie_left_rot' type='revolute'>
      <child>link_left_bogie_rot</child>
      <parent>link_right_bogie_rot</parent>
      <axis>
        <xyz>0 1 0</xyz>
        <limit>
          <lower>-1e+16</lower>
          <upper>1e+16</upper>
        </limit>
        <dynamics>
          <spring_reference>0</spring_reference>
          <spring_stiffness>0</spring_stiffness>
        </dynamics>
        <use_parent_model_frame>1</use_parent_model_frame>
      </axis>
    </joint>
    <link name='link_BLRWheel'>
      <pose frame=''>-0.400599 0.37516 -0.193184 -1.5708 -2e-06 -0</pose>
      <inertial>
        <pose frame=''>-0.003 -0.003 0.026 0 -0 0</pose>
        <mass>6.598</mass>
        <inertia>
          <ixx>0.031</ixx>
          <ixy>2.489e-07</ixy>
          <ixz>-1.24e-09</ixz>
          <iyy>0.031</iyy>
          <iyz>1.531e-08</iyz>
          <izz>0.051</izz>
        </inertia>
      </inertial>
      <collision name='link_BLRWheel_collision_collision'>
        <pose frame=''>0 0 0 0 -0 0</pose>
        <geometry>
          <cylinder>
            <length>0.098</length>
            <radius>0.1</radius>
          </cylinder>
        </geometry>
      </collision>
      <visual name='link_BLRWheel_visual_visual'>
        <pose frame=''>0 0 0 0 -0 0</pose>
        <geometry>
          <mesh>
            <scale>0.001 0.001 0.001</scale>
            <uri>model://threedrover_description/MODELS/OWR_20_DRIVE_00_ASM_ROT.stl</uri>
          </mesh>
        </geometry>
      </visual>
    </link>
    <joint name='wheel_BL' type='revolute'>
      <child>link_BLRWheel</child>
      <parent>link_left_bogie_rot</parent>
      <axis>
        <xyz>0 1 0</xyz>
        <limit>
          <lower>-1e+16</lower>
          <upper>1e+16</upper>
        </limit>
        <dynamics>
          <spring_reference>0</spring_reference>
          <spring_stiffness>0</spring_stiffness>
        </dynamics>
        <use_parent_model_frame>1</use_parent_model_frame>
      </axis>
    </joint>
    <link name='link_FLRWheel'>
      <pose frame=''>0.370001 0.37516 -0.247056 -1.5708 -2e-06 -0</pose>
      <inertial>
        <pose frame=''>-0.003 -0.003 0.026 0 -0 0</pose>
        <mass>6.598</mass>
        <inertia>
          <ixx>0.031</ixx>
          <ixy>2.489e-07</ixy>
          <ixz>-1.24e-09</ixz>
          <iyy>0.031</iyy>
          <iyz>1.531e-08</iyz>
          <izz>0.051</izz>
        </inertia>
      </inertial>
      <collision name='link_FLRWheel_collision_collision'>
        <pose frame=''>0 0 0 0 -0 0</pose>
        <geometry>
          <cylinder>
            <length>0.098</length>
            <radius>0.1</radius>
          </cylinder>
        </geometry>
      </collision>
      <visual name='link_FLRWheel_visual_visual'>
        <pose frame=''>0 0 0 0 -0 0</pose>
        <geometry>
          <mesh>
            <scale>0.001 0.001 0.001</scale>
            <uri>model://threedrover_description/MODELS/OWR_20_DRIVE_00_ASM_ROT.stl</uri>
          </mesh>
        </geometry>
      </visual>
    </link>
    <joint name='wheel_FL' type='revolute'>
      <child>link_FLRWheel</child>
      <parent>link_left_bogie_rot</parent>
      <axis>
        <xyz>0 1 0</xyz>
        <limit>
          <lower>-1e+16</lower>
          <upper>1e+16</upper>
        </limit>
        <dynamics>
          <spring_reference>0</spring_reference>
          <spring_stiffness>0</spring_stiffness>
        </dynamics>
        <use_parent_model_frame>1</use_parent_model_frame>
      </axis>
    </joint>
    <link name='link_right_bogie_rot'>
      <pose frame=''>0 -0.15516 0 1.5708 -0 0</pose>
      <inertial>
        <pose frame=''>0.014901 -0.183813 0.161131 0 -0 0</pose>
        <mass>3.66525</mass>
        <inertia>
          <ixx>0.0336884</ixx>
          <ixy>-0.0296545</ixy>
          <ixz>-0.000963609</ixz>
          <iyy>0.463543</iyy>
          <iyz>0.0108396</iyz>
          <izz>0.478989</izz>
        </inertia>
      </inertial>
      <collision name='link_right_bogie_rot_fixed_joint_lump__link_BRSWheel_collision_collision'>
        <pose frame=''>-0.37 -0.247057 0.17 0 -0 1.5708</pose>
        <geometry>
          <cylinder>
            <length>0.05</length>
            <radius>0.05</radius>
          </cylinder>
        </geometry>
      </collision>
      <collision name='link_right_bogie_rot_fixed_joint_lump__link_FRSWheel_collision_collision_1'>
        <pose frame=''>0.4006 -0.193183 0.17 0 -0 1.5708</pose>
        <geometry>
          <cylinder>
            <length>0.05</length>
            <radius>0.05</radius>
          </cylinder>
        </geometry>
      </collision>
      <visual name='link_right_bogie_rot_visual_visual'>
        <pose frame=''>0 0 0 0 -0 0</pose>
        <geometry>
          <mesh>
            <scale>0.001 0.001 0.001</scale>
            <uri>model://threedrover_description/MODELS/OWR_20_BOGIE_00_ASM_ROT.stl</uri>
          </mesh>
        </geometry>
      </visual>
      <visual name='link_right_bogie_rot_fixed_joint_lump__link_BRSWheel_visual_visual_1'>
        <pose frame=''>-0.37 -0.247057 0.17 0 -0 1.5708</pose>
        <geometry>
          <cylinder>
            <length>0.05</length>
            <radius>0.05</radius>
          </cylinder>
        </geometry>
      </visual>
      <visual name='link_right_bogie_rot_fixed_joint_lump__link_FRSWheel_visual_visual_2'>
        <pose frame=''>0.4006 -0.193183 0.17 0 -0 1.5708</pose>
        <geometry>
          <cylinder>
            <length>0.05</length>
            <radius>0.05</radius>
          </cylinder>
        </geometry>
      </visual>
    </link>
    <joint name='joint_bogie_right_rot' type='revolute'>
      <child>link_right_bogie_rot</child>
      <parent>link_chassis</parent>
      <axis>
        <xyz>0 -1 0</xyz>
        <limit>
          <lower>-1e+16</lower>
          <upper>1e+16</upper>
        </limit>
        <dynamics>
          <spring_reference>0</spring_reference>
          <spring_stiffness>0</spring_stiffness>
        </dynamics>
        <use_parent_model_frame>1</use_parent_model_frame>
      </axis>
    </joint>
    <link name='link_BRRWheel'>
      <pose frame=''>-0.37 -0.37516 -0.247057 -1.5708 -1e-06 3.14159</pose>
      <inertial>
        <pose frame=''>-0.003 -0.003 0.026 0 -0 0</pose>
        <mass>6.598</mass>
        <inertia>
          <ixx>0.031</ixx>
          <ixy>2.489e-07</ixy>
          <ixz>-1.24e-09</ixz>
          <iyy>0.031</iyy>
          <iyz>1.531e-08</iyz>
          <izz>0.051</izz>
        </inertia>
      </inertial>
      <collision name='link_BRRWheel_collision_collision'>
        <pose frame=''>0 0 0 0 -0 0</pose>
        <geometry>
          <cylinder>
            <length>0.098</length>
            <radius>0.1</radius>
          </cylinder>
        </geometry>
      </collision>
      <visual name='link_BRRWheel_visual_visual'>
        <pose frame=''>0 0 0 0 -0 0</pose>
        <geometry>
          <mesh>
            <scale>0.001 0.001 0.001</scale>
            <uri>model://threedrover_description/MODELS/OWR_20_DRIVE_00_ASM_ROT.stl</uri>
          </mesh>
        </geometry>
      </visual>
    </link>
    <joint name='wheel_BR' type='revolute'>
      <child>link_BRRWheel</child>
      <parent>link_right_bogie_rot</parent>
      <axis>
        <xyz>0 -1 0</xyz>
        <limit>
          <lower>-1e+16</lower>
          <upper>1e+16</upper>
        </limit>
        <dynamics>
          <spring_reference>0</spring_reference>
          <spring_stiffness>0</spring_stiffness>
        </dynamics>
        <use_parent_model_frame>1</use_parent_model_frame>
      </axis>
    </joint>
    <link name='link_FRRWheel'>
      <pose frame=''>0.4006 -0.37516 -0.193183 -1.5708 -1e-06 3.14159</pose>
      <inertial>
        <pose frame=''>-0.003 -0.003 0.026 0 -0 0</pose>
        <mass>6.598</mass>
        <inertia>
          <ixx>0.031</ixx>
          <ixy>2.489e-07</ixy>
          <ixz>-1.24e-09</ixz>
          <iyy>0.031</iyy>
          <iyz>1.531e-08</iyz>
          <izz>0.051</izz>
        </inertia>
      </inertial>
      <collision name='link_FRRWheel_collision_collision'>
        <pose frame=''>0 0 0 0 -0 0</pose>
        <geometry>
          <cylinder>
            <length>0.098</length>
            <radius>0.1</radius>
          </cylinder>
        </geometry>
      </collision>
      <visual name='link_FRRWheel_visual_visual'>
        <pose frame=''>0 0 0 0 -0 0</pose>
        <geometry>
          <mesh>
            <scale>0.001 0.001 0.001</scale>
            <uri>model://threedrover_description/MODELS/OWR_20_DRIVE_00_ASM_ROT.stl</uri>
          </mesh>
        </geometry>
      </visual>
    </link>
    <joint name='wheel_FR' type='revolute'>
      <child>link_FRRWheel</child>
      <parent>link_right_bogie_rot</parent>
      <axis>
        <xyz>0 -1 0</xyz>
        <limit>
          <lower>-1e+16</lower>
          <upper>1e+16</upper>
        </limit>
        <dynamics>
          <spring_reference>0</spring_reference>
          <spring_stiffness>0</spring_stiffness>
        </dynamics>
        <use_parent_model_frame>1</use_parent_model_frame>
      </axis>
    </joint>
    <static>0</static>
    <plugin name='ss_drive' filename='libgazebo_ros_skid_steer_drive.so'>
      <updateRate>100.0</updateRate>
      <robotNamespace>/</robotNamespace>
      <leftFrontJoint>wheel_FL</leftFrontJoint>
      <rightFrontJoint>wheel_FR</rightFrontJoint>
      <leftRearJoint>wheel_BL</leftRearJoint>
      <rightRearJoint>wheel_BR</rightRearJoint>
      <wheelSeparation>0.77</wheelSeparation>
      <wheelDiameter>0.2</wheelDiameter>
      <robotBaseFrame>link_chassis</robotBaseFrame>
      <torque>10</torque>
      <topicName>cmd_vel</topicName>
      <broadcastTF>0</broadcastTF>
    </plugin>
  </model>
</sdf>
